<sdf version='1.9'>
  <model name='dobot_arm_kickstarter'>
    <link name='baseLink'>
      <inertial>
        <pose>0 0 0 0 0 0</pose>
        <mass>0.5</mass>
        <inertia>
          <ixx>0.10000000000000001</ixx>
          <ixy>0</ixy>
          <ixz>0</ixz>
          <iyy>0.10000000000000001</iyy>
          <iyz>0</iyz>
          <izz>0.10000000000000001</izz>
        </inertia>
      </inertial>
      <collision name='baseLink_collision'>
        <pose>0 0 0 0 -1.5707963267948966 0</pose>
        <geometry>
          <box>
            <size>0.0050000000000000001 0.125 0.105</size>
          </box>
        </geometry>
      </collision>
      <visual name='baseLink_visual'>
        <pose>0 0 0 0 0 0</pose>
        <geometry>
          <mesh>
            <scale>1 1 1</scale>
            <uri>cad/Dobot/A3.stl</uri>
          </mesh>
        </geometry>
        <material>
          <diffuse>0.25 0.75000006 1 1</diffuse>
          <ambient>0.25 0.75000006 1 1</ambient>
        </material>
      </visual>
    </link>
    <joint name='joint_baseLink_childA' type='revolute'>
      <pose relative_to='baseLink'>0 0 0.059999999999999998 0 0 0</pose>
      <parent>baseLink</parent>
      <child>linkA</child>
      <axis>
        <xyz>0 0 1</xyz>
        <limit>
          <lower>-inf</lower>
          <upper>inf</upper>
        </limit>
        <dynamics>
          <damping>1</damping>
          <friction>0.0001</friction>
          <spring_reference>0</spring_reference>
          <spring_stiffness>0</spring_stiffness>
        </dynamics>
      </axis>
    </joint>
    <link name='linkA'>
      <pose relative_to='joint_baseLink_childA'>0 0 0 0 0 0</pose>
      <inertial>
        <pose>0 0 0 0 0 0</pose>
        <mass>0.29999999999999999</mass>
        <inertia>
          <ixx>0.048966668999999997</ixx>
          <ixy>0</ixy>
          <ixz>0</ixz>
          <iyy>0.046466667000000003</iyy>
          <iyz>0</iyz>
          <izz>0.0041666669000000002</izz>
        </inertia>
      </inertial>
      <collision name='linkA_collision'>
        <pose>0 0 0 0 0 0</pose>
        <geometry>
          <box>
            <size>0.070000000000000007 0.055 0.11</size>
          </box>
        </geometry>
      </collision>
      <visual name='linkA_visual'>
        <pose>0.032500000000000001 0 0 0 0 0</pose>
        <geometry>
          <mesh>
            <scale>1 1 1</scale>
            <uri>cad/Dobot/A1_2.stl</uri>
          </mesh>
        </geometry>
        <material>
          <diffuse>0.25 0.75000006 1 1</diffuse>
          <ambient>0.25 0.75000006 1 1</ambient>
        </material>
      </visual>
      <visual name='linkA_visual_1'>
        <pose>-0.032500000000000001 0 0 0 0 0</pose>
        <geometry>
          <mesh>
            <scale>1 1 1</scale>
            <uri>cad/Dobot/A1_2.stl</uri>
          </mesh>
        </geometry>
        <material>
          <diffuse>0.25 0.75000006 1 1</diffuse>
          <ambient>0.25 0.75000006 1 1</ambient>
        </material>
      </visual>
      <visual name='linkA_visual_2'>
        <pose>0.0050000000000000001 -0.047 0.01 0 0 0</pose>
        <geometry>
          <mesh>
            <scale>1 1 1</scale>
            <uri>cad/Dobot/A22.stl</uri>
          </mesh>
        </geometry>
        <material>
          <diffuse>0.25 0.75000006 1 1</diffuse>
          <ambient>0.25 0.75000006 1 1</ambient>
        </material>
      </visual>
      <visual name='linkA_visual_3'>
        <pose>0 -0.024500000000000001 -0.044999999999999998 0 0 0</pose>
        <geometry>
          <mesh>
            <scale>1 1 1</scale>
            <uri>cad/Dobot/A4.stl</uri>
          </mesh>
        </geometry>
        <material>
          <diffuse>0.25 0.75000006 1 1</diffuse>
          <ambient>0.25 0.75000006 1 1</ambient>
        </material>
      </visual>
    </link>
    <joint name='joint_linkAlinkA9' type='revolute'>
      <pose relative_to='linkA'>0 -0.025999999999999999 0.053999999999999999 0 0 0</pose>
      <parent>linkA</parent>
      <child>linkA9</child>
      <axis>
        <xyz>1 0 0</xyz>
        <limit>
          <lower>-inf</lower>
          <upper>inf</upper>
        </limit>
        <dynamics>
          <damping>1</damping>
          <friction>0.0001</friction>
          <spring_reference>0</spring_reference>
          <spring_stiffness>0</spring_stiffness>
        </dynamics>
      </axis>
    </joint>
    <link name='linkA9'>
      <pose relative_to='joint_linkAlinkA9'>0 0 0 0 0 0</pose>
      <inertial>
        <pose>0 0 0.074999999999999997 0 0 0</pose>
        <mass>0.10000000000000001</mass>
        <inertia>
          <ixx>0.048966668999999997</ixx>
          <ixy>0</ixy>
          <ixz>0</ixz>
          <iyy>0.046466667000000003</iyy>
          <iyz>0</iyz>
          <izz>0.0041666669000000002</izz>
        </inertia>
      </inertial>
      <collision name='linkA9_collision'>
        <pose>0 0 0.070000000000000007 0 0 0</pose>
        <geometry>
          <box>
            <size>0.0050000000000000001 0.02 0.17999999999999999</size>
          </box>
        </geometry>
      </collision>
      <visual name='linkA9_visual'>
        <pose>0 0 0.074999999999999997 0 0 0</pose>
        <geometry>
          <mesh>
            <scale>1 1 1</scale>
            <uri>cad/Dobot/A9.stl</uri>
          </mesh>
        </geometry>
        <material>
          <diffuse>0.25 0.75000006 1 1</diffuse>
          <ambient>0.25 0.75000006 1 1</ambient>
        </material>
      </visual>
    </link>
    <joint name='joint_linkAlinkB' type='revolute'>
      <pose relative_to='linkA'>0 0 0.040000000000000001 0 0 0</pose>
      <parent>linkA</parent>
      <child>linkB</child>
      <axis>
        <xyz>1 0 0</xyz>
        <limit>
          <lower>-inf</lower>
          <upper>inf</upper>
        </limit>
        <dynamics>
          <damping>1</damping>
          <friction>0.0001</friction>
          <spring_reference>0</spring_reference>
          <spring_stiffness>0</spring_stiffness>
        </dynamics>
      </axis>
    </joint>
    <link name='linkB'>
      <pose relative_to='joint_linkAlinkB'>0 0 0 0 0 0</pose>
      <inertial>
        <pose>0 0 0.074999999999999997 0 0 0</pose>
        <mass>0.10000000000000001</mass>
        <inertia>
          <ixx>0.048966668999999997</ixx>
          <ixy>0</ixy>
          <ixz>0</ixz>
          <iyy>0.046466667000000003</iyy>
          <iyz>0</iyz>
          <izz>0.0041666669000000002</izz>
        </inertia>
      </inertial>
      <collision name='linkB_collision'>
        <pose>0 0 0.074999999999999997 0 0 0</pose>
        <geometry>
          <box>
            <size>0.035999999999999997 0.035999999999999997 0.14999999999999999</size>
          </box>
        </geometry>
      </collision>
      <visual name='linkB_visual'>
        <pose>0.025000000000000001 -0.012 0.076999999999999999 1.5707959999999999 0 0</pose>
        <geometry>
          <mesh>
            <scale>1 1 1</scale>
            <uri>cad/Dobot/A12_13.stl</uri>
          </mesh>
        </geometry>
        <material>
          <diffuse>0.25 0.75000006 1 1</diffuse>
          <ambient>0.25 0.75000006 1 1</ambient>
        </material>
      </visual>
      <visual name='linkB_visual_1'>
        <pose>-0.025000000000000001 -0.012 0.076999999999999999 1.5707959999999999 0 0</pose>
        <geometry>
          <mesh>
            <scale>1 1 1</scale>
            <uri>cad/Dobot/A12_13.stl</uri>
          </mesh>
        </geometry>
        <material>
          <diffuse>0.25 0.75000006 1 1</diffuse>
          <ambient>0.25 0.75000006 1 1</ambient>
        </material>
      </visual>
    </link>
    <joint name='joint_linkBlinkC' type='revolute'>
      <pose relative_to='linkB'>0 0 0.14999999999999999 0 0 0</pose>
      <parent>linkB</parent>
      <child>linkC</child>
      <axis>
        <xyz>1 0 0</xyz>
        <limit>
          <lower>-inf</lower>
          <upper>inf</upper>
        </limit>
        <dynamics>
          <damping>1</damping>
          <friction>0.0001</friction>
          <spring_reference>0</spring_reference>
          <spring_stiffness>0</spring_stiffness>
        </dynamics>
      </axis>
    </joint>
    <link name='linkC'>
      <pose relative_to='joint_linkBlinkC'>0 0 0 0 0 0</pose>
      <inertial>
        <pose>0 0 0.080000000000000002 0 0 0</pose>
        <mass>0.10000000000000001</mass>
        <inertia>
          <ixx>0.048966668999999997</ixx>
          <ixy>0</ixy>
          <ixz>0</ixz>
          <iyy>0.046466667000000003</iyy>
          <iyz>0</iyz>
          <izz>0.0041666669000000002</izz>
        </inertia>
      </inertial>
      <collision name='linkC_collision'>
        <pose>0 0 0.074999999999999997 0 0 0</pose>
        <geometry>
          <box>
            <size>0.025999999999999999 0.025999999999999999 0.20999999999999999</size>
          </box>
        </geometry>
      </collision>
      <visual name='linkC_visual'>
        <pose>0.02 -0.0050000000000000001 0.070000000000000007 1.5707959999999999 0 0</pose>
        <geometry>
          <mesh>
            <scale>1 1 1</scale>
            <uri>cad/Dobot/A6_7.stl</uri>
          </mesh>
        </geometry>
        <material>
          <diffuse>0.25 0.75000006 1 1</diffuse>
          <ambient>0.25 0.75000006 1 1</ambient>
        </material>
      </visual>
      <visual name='linkC_visual_1'>
        <pose>-0.02 -0.0050000000000000001 0.070000000000000007 1.5707959999999999 0 0</pose>
        <geometry>
          <mesh>
            <scale>1 1 1</scale>
            <uri>cad/Dobot/A6_7.stl</uri>
          </mesh>
        </geometry>
        <material>
          <diffuse>0.25 0.75000006 1 1</diffuse>
          <ambient>0.25 0.75000006 1 1</ambient>
        </material>
      </visual>
    </link>
    <joint name='joint_linkClinkD' type='revolute'>
      <pose relative_to='linkC'>0 0 0.16 0 0 0</pose>
      <parent>linkC</parent>
      <child>linkD</child>
      <axis>
        <xyz>1 0 0</xyz>
        <limit>
          <lower>-inf</lower>
          <upper>inf</upper>
        </limit>
        <dynamics>
          <damping>1</damping>
          <friction>0.0001</friction>
          <spring_reference>0</spring_reference>
          <spring_stiffness>0</spring_stiffness>
        </dynamics>
      </axis>
    </joint>
    <link name='linkD'>
      <pose relative_to='joint_linkClinkD'>0 0 0 0 0 0</pose>
      <inertial>
        <pose>0 0 0.02 0 0 0</pose>
        <mass>0.10000000000000001</mass>
        <inertia>
          <ixx>0.048966668999999997</ixx>
          <ixy>0</ixy>
          <ixz>0</ixz>
          <iyy>0.046466667000000003</iyy>
          <iyz>0</iyz>
          <izz>0.0041666669000000002</izz>
        </inertia>
      </inertial>
      <collision name='linkD_collision'>
        <pose>0 0.044999999999999998 -0.017000000000000001 0 0 0</pose>
        <geometry>
          <box>
            <size>0.02 0.080000000000000002 0.0050000000000000001</size>
          </box>
        </geometry>
      </collision>
      <visual name='linkD_visual'>
        <pose>0 0.010999999999999999 0 0 0 0</pose>
        <geometry>
          <mesh>
            <scale>1 1 1</scale>
            <uri>cad/Dobot/A17.stl</uri>
          </mesh>
        </geometry>
        <material>
          <diffuse>0.25 0.75000006 1 1</diffuse>
          <ambient>0.25 0.75000006 1 1</ambient>
        </material>
      </visual>
      <visual name='linkD_visual_1'>
        <pose>0 0 0 0 0 0</pose>
        <geometry>
          <mesh>
            <scale>1 1 1</scale>
            <uri>cad/Dobot/A16.stl</uri>
          </mesh>
        </geometry>
        <material>
          <diffuse>0.25 0.75000006 1 1</diffuse>
          <ambient>0.25 0.75000006 1 1</ambient>
        </material>
      </visual>
    </link>
    <joint name='joint_linkBlinkC2' type='revolute'>
      <pose relative_to='linkB'>0 0 0.14999999999999999 0 0 0</pose>
      <parent>linkB</parent>
      <child>linkC2</child>
      <axis>
        <xyz>1 0 0</xyz>
        <limit>
          <lower>-inf</lower>
          <upper>inf</upper>
        </limit>
        <dynamics>
          <damping>1</damping>
          <friction>0.0001</friction>
          <spring_reference>0</spring_reference>
          <spring_stiffness>0</spring_stiffness>
        </dynamics>
      </axis>
    </joint>
    <link name='linkC2'>
      <pose relative_to='joint_linkBlinkC2'>0 0 0 0 0 0</pose>
      <inertial>
        <pose>0 0 0 0 0 0</pose>
        <mass>0.10000000000000001</mass>
        <inertia>
          <ixx>0.048966668999999997</ixx>
          <ixy>0</ixy>
          <ixz>0</ixz>
          <iyy>0.046466667000000003</iyy>
          <iyz>0</iyz>
          <izz>0.0041666669000000002</izz>
        </inertia>
      </inertial>
      <collision name='linkC2_collision'>
        <pose>0 0 0 0 0 0</pose>
        <geometry>
          <box>
            <size>0.0050000000000000001 0.050000000000000003 0.031</size>
          </box>
        </geometry>
      </collision>
      <visual name='linkC2_visual'>
        <pose>0 0 0 0 0 0</pose>
        <geometry>
          <mesh>
            <scale>1 1 1</scale>
            <uri>cad/Dobot/A11.stl</uri>
          </mesh>
        </geometry>
        <material>
          <diffuse>0.25 0.75000006 1 1</diffuse>
          <ambient>0.25 0.75000006 1 1</ambient>
        </material>
      </visual>
    </link>
    <joint name='joint_linkC2linkA10' type='revolute'>
      <pose relative_to='linkC2'>0 0.025999999999999999 0.014 0 0 0</pose>
      <parent>linkC2</parent>
      <child>linkA10</child>
      <axis>
        <xyz>1 0 0</xyz>
        <limit>
          <lower>-inf</lower>
          <upper>inf</upper>
        </limit>
        <dynamics>
          <damping>1</damping>
          <friction>0.0001</friction>
          <spring_reference>0</spring_reference>
          <spring_stiffness>0</spring_stiffness>
        </dynamics>
      </axis>
    </joint>
    <link name='linkA10'>
      <pose relative_to='joint_linkC2linkA10'>0 0 0 0 0 0</pose>
      <inertial>
        <pose>0 0 0.080000000000000002 0 0 0</pose>
        <mass>0.10000000000000001</mass>
        <inertia>
          <ixx>0.048966668999999997</ixx>
          <ixy>0</ixy>
          <ixz>0</ixz>
          <iyy>0.046466667000000003</iyy>
          <iyz>0</iyz>
          <izz>0.0041666669000000002</izz>
        </inertia>
      </inertial>
      <collision name='linkA10_collision'>
        <pose>0 0 0.080000000000000002 0 0 0</pose>
        <geometry>
          <box>
            <size>0.0050000000000000001 0.02 0.17000000000000001</size>
          </box>
        </geometry>
      </collision>
      <visual name='linkA10_visual'>
        <pose>0 0 0.080000000000000002 0 0 0</pose>
        <geometry>
          <mesh>
            <scale>1 1 1</scale>
            <uri>cad/Dobot/A10.stl</uri>
          </mesh>
        </geometry>
        <material>
          <diffuse>0.25 0.75000006 1 1</diffuse>
          <ambient>0.25 0.75000006 1 1</ambient>
        </material>
      </visual>
    </link>
    <joint name='joint_linkAmotorA' type='revolute'>
      <pose relative_to='linkA'>0.050000000000000003 0 0.029999999999999999 0 0 0</pose>
      <parent>linkA</parent>
      <child>motorA</child>
      <axis>
        <xyz>1 0 0</xyz>
        <limit>
          <lower>-inf</lower>
          <upper>inf</upper>
        </limit>
        <dynamics>
          <damping>1</damping>
          <friction>0.0001</friction>
          <spring_reference>0</spring_reference>
          <spring_stiffness>0</spring_stiffness>
        </dynamics>
      </axis>
    </joint>
    <link name='motorA'>
      <pose relative_to='joint_linkAmotorA'>0 0 0 0 0 0</pose>
      <inertial>
        <pose>0 0 0 0 1.5700000000004057 0</pose>
        <mass>0.10000000000000001</mass>
        <inertia>
          <ixx>0.048966668999999997</ixx>
          <ixy>0</ixy>
          <ixz>0</ixz>
          <iyy>0.046466667000000003</iyy>
          <iyz>0</iyz>
          <izz>0.0041666669000000002</izz>
        </inertia>
      </inertial>
      <collision name='motorA_collision'>
        <pose>0 0 0 0 1.5707963267948966 0</pose>
        <geometry>
          <cylinder>
            <length>0.029999999999999999</length>
            <radius>0.02</radius>
          </cylinder>
        </geometry>
      </collision>
      <visual name='motorA_visual'>
        <pose>0 0 0 0 1.5707963267948966 0</pose>
        <geometry>
          <cylinder>
            <length>0.029999999999999999</length>
            <radius>0.02</radius>
          </cylinder>
        </geometry>
        <material>
          <diffuse>0.25 0.25 0.25 1</diffuse>
          <ambient>0.25 0.25 0.25 1</ambient>
        </material>
      </visual>
    </link>
    <joint name='joint_linkAmotorB' type='revolute'>
      <pose relative_to='linkA'>-0.050000000000000003 0 0.029999999999999999 0 0 0</pose>
      <parent>linkA</parent>
      <child>motorB</child>
      <axis>
        <xyz>-1 0 0</xyz>
        <limit>
          <lower>-inf</lower>
          <upper>inf</upper>
        </limit>
        <dynamics>
          <damping>1</damping>
          <friction>0.0001</friction>
          <spring_reference>0</spring_reference>
          <spring_stiffness>0</spring_stiffness>
        </dynamics>
      </axis>
    </joint>
    <link name='motorB'>
      <pose relative_to='joint_linkAmotorB'>0 0 0 0 0 0</pose>
      <inertial>
        <pose>0 0 0 0 1.5700000000004057 0</pose>
        <mass>0.10000000000000001</mass>
        <inertia>
          <ixx>0.048966668999999997</ixx>
          <ixy>0</ixy>
          <ixz>0</ixz>
          <iyy>0.046466667000000003</iyy>
          <iyz>0</iyz>
          <izz>0.0041666669000000002</izz>
        </inertia>
      </inertial>
      <collision name='motorB_collision'>
        <pose>0 0 0 0 1.5707963267948966 0</pose>
        <geometry>
          <cylinder>
            <length>0.029999999999999999</length>
            <radius>0.02</radius>
          </cylinder>
        </geometry>
      </collision>
      <visual name='motorB_visual'>
        <pose>0 0 0 0 1.5707963267948966 0</pose>
        <geometry>
          <cylinder>
            <length>0.029999999999999999</length>
            <radius>0.02</radius>
          </cylinder>
        </geometry>
        <material>
          <diffuse>0.25 0.25 0.25 1</diffuse>
          <ambient>0.25 0.25 0.25 1</ambient>
        </material>
      </visual>
    </link>
  </model>
</sdf>
